Workbook

Sheet Income Statement
A1: Particulars | B1: Mar-15 | C1: Mar-16 | D1: Mar-17 | E1: Mar-18 | F1: Mar-19 | G1: Mar-20 | H1: Mar-21 | I1: Mar-22 | J1: Mar-23 | K1: Mar-24 | L1: Mar-25 | M1: Mar-26 | N1: TTM
A2: Sales - | B2: 12103 | C2: 13772 | D2: 14910 | E2: 16463 | F2: 19564 | G2: 23099 | H2: 24775 | I2: 23455 | J2: 24855 | K2: 29002 | L2: 31724 | M2: 33653 | N2: 34935
A3: Sales Growth % | B3: 0.4963 | C3: 0.1378 | D3: 0.0826 | E3: 0.1042 | F3: 0.1883 | G3: 0.1807 | H3: 0.0726 | I3: -0.0532 | J3: 0.0597 | K3: 0.1668 | L3: 0.0939 | M3: 0.0608
A4: Expenses - | B4: 9524 | C4: 10579 | D4: 11469 | E4: 12691 | F4: 15612 | G4: 18249 | H4: 19497 | I4: 19060 | J4: 21148 | K4: 23176 | L4: 25164 | M4: 26783 | N4: 27854
A5: Material Cost % - | B5: 0.4529 | C5: 0.4474 | D5: 0.4316 | E5: 0.4102 | F5: 0.4454 | G5: 0.4215 | H5: 0.3997 | I5: 0.4323 | J5: 0.4544 | K5: 0.4346 | L5: 0.4106 | M5: 0.4008
A6: Raw material cost | B6: 5835 | C6: 6255 | D6: 6743 | E6: 7235 | F6: 9388 | G6: 9837 | H6: 10633 | I6: 9324 | J6: 11703 | K6: 13549 | L6: 13624 | M6: 13783
A7: Change in inventory | B7: -329 | C7: -93 | D7: -309 | E7: -483 | F7: -676 | G7: -102 | H7: -730 | I7: 817 | J7: -410 | K7: -946 | L7: -598 | M7: -295
A8: Manufacturing Cost % | B8: 0.0741 | C8: 0.0733 | D8: 0.0725 | E8: 0.0739 | F8: 0.0772 | G8: 0.0672 | H8: 0.0686 | I8: 0.0718 | J8: 0.0752 | K8: 0.0679 | L8: 0.0729 | M8: 0.0769
A9: Employee Cost % | B9: 0.1076 | C9: 0.112 | D9: 0.1186 | E9: 0.1295 | F9: 0.1321 | G9: 0.1394 | H9: 0.1427 | I9: 0.1472 | J9: 0.1418 | K9: 0.1353 | L9: 0.1412 | M9: 0.1543
A10: Other Cost % | B10: 0.1503 | C10: 0.1354 | D10: 0.1466 | E10: 0.1574 | F10: 0.1433 | G10: 0.162 | H10: 0.1759 | I10: 0.1613 | J10: 0.1795 | K10: 0.1614 | L10: 0.1685 | M10: 0.1638
A11: Operating Profit | B11: 2579 | C11: 3193 | D11: 3441 | E11: 3772 | F11: 3952 | G11: 4849 | H11: 5278 | I11: 4396 | J11: 3707 | K11: 5826 | L11: 6560 | M11: 6870 | N11: 7081
A12: OPM % | B12: 0.21 | C12: 0.23 | D12: 0.23 | E12: 0.23 | F12: 0.2 | G12: 0.21 | H12: 0.21 | I12: 0.19 | J12: 0.15 | K12: 0.2 | L12: 0.21 | M12: 0.2 | N12: 0.2
A13: Other Income - | B13: 81 | C13: 200 | D13: 115 | E13: 105 | F13: 70 | G13: 166 | H13: 3195 | I13: 152 | J13: 291 | K13: 366 | L13: 613 | M13: 404 | N13: 586
A14: Exceptional items | B14: -16 | C14: -5 | D14: -6 | E14: 0 | F14: -88 | G14: -26 | H14: 2815 | I14: -139 | J14: 13 | K14: -168 | L14: 25 | M14: -88
A15: Other income normal | B15: 97 | C15: 205 | D15: 121 | E15: 105 | F15: 158 | G15: 192 | H15: 381 | I15: 291 | J15: 277 | K15: 534 | L15: 588 | M15: 492
A16: Interest | B16: 160 | C16: 257 | D16: 67 | E16: 78 | F16: 263 | G16: 305 | H16: 74 | I16: 49 | J16: 140 | K16: 290 | L16: 457 | M16: 384 | N16: 388
A17: Depreciation | B17: 333 | C17: 392 | D17: 428 | E17: 558 | F17: 668 | G17: 967 | H17: 1055 | I17: 1127 | J17: 1245 | K17: 1522 | L17: 1649 | M17: 1778 | N17: 1859
A18: Profit before tax | B18: 2168 | C18: 2744 | D18: 3061 | E18: 3241 | F18: 3091 | G18: 3743 | H18: 7344 | I18: 3373 | J18: 2612 | K18: 4380 | L18: 5066 | M18: 5112 | N18: 5420
A19: Tax % | B19: 0.28 | C19: 0.26 | D19: 0.25 | E19: 0.25 | F19: 0.24 | G19: 0.24 | H19: 0.27 | I19: 0.22 | J19: 0.26 | K19: 0.28 | L19: 0.31 | M19: 0.31
A20: Net Profit - | B20: 1571 | C20: 2024 | D20: 2301 | E20: 2423 | F20: 2364 | G20: 2844 | H20: 5334 | I20: 2647 | J20: 1928 | K20: 3169 | L20: 3484 | M20: 3503 | N20: 3711
A21: Minority share | B21: 5 | C21: 2 | D21: 0 | E21: 0 | F21: 0 | G21: 1 | H21: 1 | I21: 1 | J21: 0 | K21: 4 | L21: 2 | M21: 2
A22: Exceptional items AT | B22: -11 | C22: -4 | D22: -5 | E22: 0 | F22: -66 | G22: -20 | H22: 1925 | I22: -109 | J22: 8 | K22: -100 | L22: 33 | M22: -58
A23: Profit excl Excep | B23: 1583 | C23: 2027 | D23: 2306 | E23: 2423 | F23: 2430 | G23: 2863 | H23: 3409 | I23: 2756 | J23: 1920 | K23: 3269 | L23: 3451 | M23: 3561
A24: Profit for PE | B24: 1587 | C24: 2029 | D24: 2306 | E24: 2423 | F24: 2431 | G24: 2865 | H24: 3410 | I24: 2757 | J24: 1920 | K24: 3273 | L24: 3453 | M24: 3563
A25: Profit for EPS | B25: 1576 | C25: 2025 | D25: 2302 | E25: 2423 | F25: 2365 | G25: 2845 | H25: 5335 | I25: 2648 | J25: 1928 | K25: 3173 | L25: 3486 | M25: 3505
A26: Profit Growth % | B26: 0.35 | C26: 0.28 | D26: 0.14 | E26: 0.05 | F26: 0 | G26: 0.18 | H26: 0.19 | I26: -0.19 | J26: -0.3 | K26: 0.7 | L26: 0.06 | M26: 0.03
A27: EPS in Rs | B27: 26.98 | C27: 34.61 | D27: 39.29 | E27: 41.36 | F27: 40.36 | G27: 48.56 | H27: 91.05 | I27: 45.2 | J27: 32.9 | K27: 54.15 | L27: 60.02 | M27: 60.34 | N27: 64.09
A28: Dividend Payout % | B28: 0.08 | C28: 0.07 | D28: 0.06 | E28: 0.06 | F28: 0.06 | G28: 0.06 | H28: 0.04 | I28: 0.2 | J28: 0.23 | K28: 0.08 | L28: 0 | M28: 0.07

Sheet Balance Sheet
A1: Particulars | B1: Mar 2015 | C1: Mar 2016 | D1: Mar 2017 | E1: Mar 2018 | F1: Mar 2019 | G1: Mar 2020 | H1: Mar 2021 | I1: Mar 2022 | J1: Mar 2023 | K1: Mar 2024 | L1: Mar 2025 | M1: Mar 2026
A2: Equity Capital | B2: 29 | C2: 59 | D2: 59 | E2: 59 | F2: 59 | G2: 59 | H2: 59 | I2: 59 | J2: 59 | K2: 59 | L2: 58 | M2: 58
A3: Reserves | B3: 5127 | C3: 7229 | D3: 9313 | E3: 11622 | F3: 13832 | G3: 16766 | H3: 21871 | I3: 24517 | J3: 26781 | K3: 29784 | L3: 32595 | M3: 37833
A4: Borrowings | B4: 4451 | C4: 5041 | D4: 3364 | E4: 4770 | F4: 6967 | G4: 5826 | H4: 5339 | I4: 2851 | J4: 5286 | K4: 6648 | L4: 8263 | M4: 8073
A5: Long term Borrowings | B5: 1361 | C5: 743 | D5: 181 | E5: 451 | F5: 180 | G5: 0 | H5: 168 | I5: 249 | J5: 619 | K5: 2135 | L5: 1562 | M5: 803
A6: Short term Borrowings | B6: 2502 | C6: 3673 | D6: 2903 | E6: 4031 | F6: 6573 | G6: 5422 | H6: 4804 | I6: 2124 | J6: 4243 | K6: 4180 | L6: 6380 | M6: 6873
A7: Lease Liabilities | B7: 0 | C7: 0 | D7: 0 | E7: 0 | F7: 0 | G7: 264 | H7: 367 | I7: 478 | J7: 425 | K7: 332 | L7: 321 | M7: 397
A8: Preference Capital | B8: 0 | C8: 0 | D8: 0 | E8: 0 | F8: 0 | G8: 0 | H8: 0 | I8: 0 | J8: 0 | K8: 0 | L8: 2 | M8: 5
A9: Other Borrowings | B9: 588 | C9: 626 | D9: 280 | E9: 287 | F9: 214 | G9: 140 | H9: 0 | I9: 0 | J9: 0 | K9: 0 | L9: -2 | M9: -5
A10: Other Liabilities | B10: 3303 | C10: 3568 | D10: 3464 | E10: 4492 | F10: 5414 | G10: 6113 | H10: 6147 | I10: 6211 | J10: 7379 | K10: 8227 | L10: 8566 | M10: 12232
A11: Non controlling int | B11: 26 | C11: 3 | D11: 2 | E11: 2 | F11: 2 | G11: 0 | H11: -1 | I11: -2 | J11: 12 | K11: 8 | L11: -6 | M11: -8
A12: Trade Payables | B12: 2051 | C12: 2457 | D12: 2155 | E12: 2373 | F12: 2552 | G12: 2576 | H12: 2795 | I12: 2703 | J12: 3871 | K12: 4454 | L12: 4189 | M12: 5567
A13: Advance from Customers | B13: 4 | C13: 6 | D13: 39 | E13: 67 | F13: 167 | G13: 21 | H13: 0 | I13: 0 | J13: 0 | K13: 0 | L13: 0 | M13: 0
A14: Other liability items | C14: 1103 | D14: 1268 | E14: 2050 | F14: 2693 | G14: 3516 | H14: 3353 | I14: 3510 | J14: 3496 | K14: 3765 | L14: 4383 | M14: 6673
A15: Total Liabilities & Equity | B15: 12910 | C15: 15896 | D15: 16200 | E15: 20942 | F15: 26271 | G15: 28765 | H15: 33416 | I15: 33638 | J15: 39505 | K15: 44717 | L15: 49482 | M15: 58196
A16: Fixed Assets | B16: 3706 | C16: 4180 | D16: 4834 | E16: 6521 | F16: 8475 | G16: 9396 | H16: 9374 | I16: 10532 | J16: 11024 | K16: 14493 | L16: 14794 | M16: 17407
A17: Land | B17: 142 | C17: 325 | D17: 454 | E17: 236 | F17: 254 | G17: 253 | H17: 286 | I17: 781 | J17: 955 | K17: 979 | L17: 1007 | M17: 1186
A18: Building | B18: 950 | C18: 915 | D18: 1124 | E18: 1606 | F18: 1897 | G18: 2276 | H18: 2418 | I18: 2841 | J18: 3592 | K18: 4916 | L18: 4735 | M18: 5623
A19: Plant Machinery | B19: 3148 | C19: 2376 | D19: 3068 | E19: 3878 | F19: 4993 | G19: 5624 | H19: 6444 | I19: 7489 | J19: 8433 | K19: 11048 | L19: 11993 | M19: 14275
A20: Equipments | B20: 47 | C20: 27 | D20: 33 | E20: 47 | F20: 71 | G20: 88 | H20: 90 | I20: 112 | J20: 166 | K20: 506 | L20: 448 | M20: 499
A21: Furniture n fittings | B21: 98 | C21: 70 | D21: 98 | E21: 127 | F21: 163 | G21: 180 | H21: 186 | I21: 243 | J21: 268 | K21: 297 | L21: 343 | M21: 418
A22: Vehicles | B22: 17 | C22: 11 | D22: 23 | E22: 26 | F22: 50 | G22: 27 | H22: 34 | I22: 131 | J22: 142 | K22: 172 | L22: 201 | M22: 234
A23: Intangible Assets | B23: 1034 | C23: 844 | D23: 836 | E23: 1974 | F23: 3069 | G23: 3464 | H23: 3581 | I23: 3928 | J23: 5039 | K23: 5530 | L23: 5735 | M23: 7017
A24: Other fixed assets | B24: 10 | C24: 0 | D24: 0 | E24: 0 | F24: 0 | G24: 530 | H24: 574 | I24: 0 | J24: 0 | K24: 0 | L24: 0 | M24: 0
A25: Gross Block | B25: 5446 | C25: 4570 | D25: 5635 | E25: 7895 | F25: 10498 | G25: 12441 | H25: 13613 | I25: 15525 | J25: 18593 | K25: 23448 | L25: 24463 | M25: 29251
A26: Accumulated Depreciation | B26: 1740 | C26: 390 | D26: 802 | E26: 1374 | F26: 2023 | G26: 3045 | H26: 4240 | I26: 4992 | J26: 7570 | K26: 8955 | L26: 9669 | M26: 11844
... A35: Total Assets | B35: 12910 | C35: 15896 | D35: 16200 | E35: 20942 | F35: 26271 | G35: 28765 | H35: 33416 | I35: 33638 | J35: 39505 | K35: 44717 | L35: 49482 | M35: 58196

Sheet Hortizontal Analysis
A1: Horizontal Analysis - Income Statement
A3: Particulars | B3: 42064 | C3: 42430 | D3: Change | E3: %Change | F3: 42795 | G3: Change | H3: %Change | I3: 43160 | J3: Change | K3: %Change | L3: 43525 | M3: Change | N3: %Change | O3: 43891 | P3: Change | Q3: %Change | R3: 44256 | S3: Change | T3: %Change | U3: 44621 | V3: Change | W3: %Change | X3: 44986 | Y3: Change | Z3: %Change | AA3: 45352 | AB3: Change | AC3: %Change | AD3: 45717 | AE3: Change | AF3: %Change | AG3: 46082 | AH3: Change | AI3: %Change
A4: Sales | B4: 12103 | C4: 13772 | D4: =C4-B4 -> 1669 | E4: =(C4-B4)/B4*100 -> 13.789969 | F4: 14910 | G4: =F4-C4 -> 1138 | H4: =(F4-C4)/C4*100 -> 8.2631426 | I4: 16463 | J4: =I4-F4 -> 1553 | K4: =(I4-F4)/F4*100 -> 10.415828 | L4: 19564 | M4: =L4-I4 -> 3101 | N4: =(L4-I4)/I4*100 -> 18.836178 | O4: 23099 | P4: =O4-L4 -> 3535 | Q4: =(O4-L4)/L4*100 -> 18.068902 | R4: 24775 | S4: =R4-O4 -> 1676 | T4: =(R4-O4)/O4*100 -> 7.2557254 | U4: 23455 | V4: =U4-R4 -> -1320 | W4: =(U4-R4)/R4*100 -> -5.3279516 | X4: 24855 | Y4: =X4-U4 -> 1400 | Z4: =(X4-U4)/U4*100 -> 5.9688766 | AA4: 29002 | AB4: =AA4-X4 -> 4147 | AC4: =(AA4-X4)/X4*100 -> 16.684772 | AD4: 31724 | AE4: =AD4-AA4 -> 2722 | AF4: =(AD4-AA4)/AA4*100 -> 9.3855596 | AG4: 33653 | AH4: =AG4-AD4 -> 1929 | AI4: =(AG4-AD4)/AD4*100 -> 6.0805699
A5: Expenses | B5: 9524 | C5: 10579 | D5: =C5-B5 -> 1055 | E5: =(C5-B5)/B5*100 -> 11.077278 | F5: 11469 | G5: =F5-C5 -> 890 | H5: =(F5-C5)/C5*100 -> 8.4128935 | I5: 12691 | J5: =I5-F5 -> 1222 | K5: =(I5-F5)/F5*100 -> 10.654809 | L5: 15612 | M5: =L5-I5 -> 2921 | N5: =(L5-I5)/I5*100 -> 23.016311 | O5: 18249 | P5: =O5-L5 -> 2637 | Q5: =(O5-L5)/L5*100 -> 16.890853 | R5: 19497 | S5: =R5-O5 -> 1248 | T5: =(R5-O5)/O5*100 -> 6.8387309 | U5: 19060 | V5: =U5-R5 -> -437 | W5: =(U5-R5)/R5*100 -> -2.2413705 | X5: 21148 | Y5: =X5-U5 -> 2088 | Z5: =(X5-U5)/U5*100 -> 10.954879 | AA5: 23176 | AB5: =AA5-X5 -> 2028 | AC5: =(AA5-X5)/X5*100 -> 9.5895593 | AD5: 25164 | AE5: =AD5-AA5 -> 1988 | AF5: =(AD5-AA5)/AA5*100 -> 8.5778391 | AG5: 26783 | AH5: =AG5-AD5 -> 1619 | AI5: =(AG5-AD5)/AD5*100 -> 6.4337943
A6: Operating Profit | B6: 2579 | C6: 3193 | D6: =C6-B6 -> 614 | E6: =(C6-B6)/B6*100 -> 23.807677 | F6: 3441 | G6: =F6-C6 -> 248 | H6: =(F6-C6)/C6*100 -> 7.7669903 | I6: 3772 | J6: =I6-F6 -> 331 | K6: =(I6-F6)/F6*100 -> 9.6192967 | L6: 3952 | M6: =L6-I6 -> 180 | N6: =(L6-I6)/I6*100 -> 4.7720042 | O6: 4849 | P6: =O6-L6 -> 897 | Q6: =(O6-L6)/L6*100 -> 22.697368 | R6: 5278 | S6: =R6-O6 -> 429 | T6: =(R6-O6)/O6*100 -> 8.847185 | U6: 4396 | V6: =U6-R6 -> -882 | W6: =(U6-R6)/R6*100 -> -16.710875 | X6: 3707 | Y6: =X6-U6 -> -689 | Z6: =(X6-U6)/U6*100 -> -15.673339 | AA6: 5826 | AB6: =AA6-X6 -> 2119 | AC6: =(AA6-X6)/X6*100 -> 57.162126 | AD6: 6560 | AE6: =AD6-AA6 -> 734 | AF6: =(AD6-AA6)/AA6*100 -> 12.598696 | AG6: 6870 | AH6: =AG6-AD6 -> 310 | AI6: =(AG6-AD6)/AD6*100 -> 4.7256098
A7: Other Income | B7: 81 | C7: 200 | D7: =C7-B7 -> 119 | E7: =(C7-B7)/B7*100 -> 146.91358 | F7: 115 | G7: =F7-C7 -> -85 | H7: =(F7-C7)/C7*100 -> -42.5 | I7: 105 | J7: =I7-F7 -> -10 | K7: =(I7-F7)/F7*100 -> -8.6956522 | L7: 70 | M7: =L7-I7 -> -35 | N7: =(L7-I7)/I7*100 -> -33.333333 | O7: 166 | P7: =O7-L7 -> 96 | Q7: =(O7-L7)/L7*100 -> 137.14286 | R7: 3195 | S7: =R7-O7 -> 3029 | T7: =(R7-O7)/O7*100 -> 1824.6988 | U7: 152 | V7: =U7-R7 -> -3043 | W7: =(U7-R7)/R7*100 -> -95.242567 | X7: 291 | Y7: =X7-U7 -> 139 | Z7: =(X7-U7)/U7*100 -> 91.447368 | AA7: 366 | AB7: =AA7-X7 -> 75 | AC7: =(AA7-X7)/X7*100 -> 25.773196 | AD7: 613 | AE7: =AD7-AA7 -> 247 | AF7: =(AD7-AA7)/AA7*100 -> 67.486339 | AG7: 404 | AH7: =AG7-AD7 -> -209 | AI7: =(AG7-AD7)/AD7*100 -> -34.094617
A8: Interest | B8: 160 | C8: 257 | D8: =C8-B8 -> 97 | E8: =(C8-B8)/B8*100 -> 60.625 | F8: 67 | G8: =F8-C8 -> -190 | H8: =(F8-C8)/C8*100 -> -73.929961 | I8: 78 | J8: =I8-F8 -> 11 | K8: =(I8-F8)/F8*100 -> 16.41791 | L8: 263 | M8: =L8-I8 -> 185 | N8: =(L8-I8)/I8*100 -> 237.17949 | O8: 305 | P8: =O8-L8 -> 42 | Q8: =(O8-L8)/L8*100 -> 15.969582 | R8: 74 | S8: =R8-O8 -> -231 | T8: =(R8-O8)/O8*100 -> -75.737705 | U8: 49 | V8: =U8-R8 -> -25 | W8: =(U8-R8)/R8*100 -> -33.783784 | X8: 140 | Y8: =X8-U8 -> 91 | Z8: =(X8-U8)/U8*100 -> 185.71429 | AA8: 290 | AB8: =AA8-X8 -> 150 | AC8: =(AA8-X8)/X8*100 -> 107.14286 | AD8: 457 | AE8: =AD8-AA8 -> 167 | AF8: =(AD8-AA8)/AA8*100 -> 57.586207 | AG8: 384 | AH8: =AG8-AD8 -> -73 | AI8: =(AG8-AD8)/AD8*100 -> -15.973742
A9: Depreciation | B9: 333 | C9: 392 | D9: =C9-B9 -> 59 | E9: =(C9-B9)/B9*100 -> 17.717718 | F9: 428 | G9: =F9-C9 -> 36 | H9: =(F9-C9)/C9*100 -> 9.1836735 | I9: 558 | J9: =I9-F9 -> 130 | K9: =(I9-F9)/F9*100 -> 30.373832 | L9: 668 | M9: =L9-I9 -> 110 | N9: =(L9-I9)/I9*100 -> 19.713262 | O9: 967 | P9: =O9-L9 -> 299 | Q9: =(O9-L9)/L9*100 -> 44.760479 | R9: 1055 | S9: =R9-O9 -> 88 | T9: =(R9-O9)/O9*100 -> 9.1003102 | U9: 1127 | V9: =U9-R9 -> 72 | W9: =(U9-R9)/R9*100 -> 6.8246445 | X9: 1245 | Y9: =X9-U9 -> 118 | Z9: =(X9-U9)/U9*100 -> 10.470275 | AA9: 1522 | AB9: =AA9-X9 -> 277 | AC9: =(AA9-X9)/X9*100 -> 22.248996 | AD9: 1649 | AE9: =AD9-AA9 -> 127 | AF9: =(AD9-AA9)/AA9*100 -> 8.3442838 | AG9: 1778 | AH9: =AG9-AD9 -> 129 | AI9: =(AG9-AD9)/AD9*100 -> 7.822923
A10: Profit Before Tax | B10: 2168 | C10: 2744 | D10: =C10-B10 -> 576 | E10: =(C10-B10)/B10*100 -> 26.568266 | F10: 3061 | G10: =F10-C10 -> 317 | H10: =(F10-C10)/C10*100 -> 11.552478 | I10: 3241 | J10: =I10-F10 -> 180 | K10: =(I10-F10)/F10*100 -> 5.8804312 | L10: 3091 | M10: =L10-I10 -> -150 | N10: =(L10-I10)/I10*100 -> -4.6282012 | O10: 3743 | P10: =O10-L10 -> 652 | Q10: =(O10-L10)/L10*100 -> 21.093497 | R10: 7344 | S10: =R10-O10 -> 3601 | T10: =(R10-O10)/O10*100 -> 96.206252 | U10: 3373 | V10: =U10-R10 -> -3971 | W10: =(U10-R10)/R10*100 -> -54.071351 | X10: 2612 | Y10: =X10-U10 -> -761 | Z10: =(X10-U10)/U10*100 -> -22.561518 | AA10: 4380 | AB10: =AA10-X10 -> 1768 | AC10: =(AA10-X10)/X10*100 -> 67.687596 | AD10: 5066 | AE10: =AD10-AA10 -> 686 | AF10: =(AD10-AA10)/AA10*100 -> 15.6621 | AG10: 5112 | AH10: =AG10-AD10 -> 46 | AI10: =(AG10-AD10)/AD10*100 -> 0.90801421
A11: Net Profit | B11: 1571 | C11: 2024 | D11: =C11-B11 -> 453 | E11: =(C11-B11)/B11*100 -> 28.835137 | F11: 2301 | G11: =F11-C11 -> 277 | H11: =(F11-C11)/C11*100 -> 13.685771 | I11: 2423 | J11: =I11-F11 -> 122 | K11: =(I11-F11)/F11*100 -> 5.3020426 | L11: 2364 | M11: =L11-I11 -> -59 | N11: =(L11-I11)/I11*100 -> -2.4349979 | O11: 2844 | P11: =O11-L11 -> 480 | Q11: =(O11-L11)/L11*100 -> 20.304569 | R11: 5334 | S11: =R11-O11 -> 2490 | T11: =(R11-O11)/O11*100 -> 87.552743 | U11: 2647 | V11: =U11-R11 -> -2687 | W11: =(U11-R11)/R11*100 -> -50.374953 | X11: 1928 | Y11: =X11-U11 -> -719 | Z11: =(X11-U11)/U11*100 -> -27.162826 | AA11: 3169 | AB11: =AA11-X11 -> 1241 | AC11: =(AA11-X11)/X11*100 -> 64.36722 | AD11: 3484 | AE11: =AD11-AA11 -> 315 | AF11: =(AD11-AA11)/AA11*100 -> 9.9400442 | AG11: 3503 | AH11: =AG11-AD11 -> 19 | AI11: =(AG11-AD11)/AD11*100 -> 0.54535017
A12: EPS | B12: 26.98 | C12: 34.61 | D12: =C12-B12 -> 7.63 | E12: =(C12-B12)/B12*100 -> 28.280208 | F12: 39.29 | G12: =F12-C12 -> 4.68 | H12: =(F12-C12)/C12*100 -> 13.522103 | I12: 41.36 | J12: =I12-F12 -> 2.07 | K12: =(I12-F12)/F12*100 -> 5.2685162 | L12: 40.36 | M12: =L12-I12 -> -1 | N12: =(L12-I12)/I12*100 -> -2.417795 | O12: 48.56 | P12: =O12-L12 -> 8.2 | Q12: =(O12-L12)/L12*100 -> 20.317146 | R12: 91.05 | S12: =R12-O12 -> 42.49 | T12: =(R12-O12)/O12*100 -> 87.5 | U12: 45.2 | V12: =U12-R12 -> -45.85 | W12: =(U12-R12)/R12*100 -> -50.356947 | X12: 32.9 | Y12: =X12-U12 -> -12.3 | Z12: =(X12-U12)/U12*100 -> -27.212389 | AA12: 54.15 | AB12: =AA12-X12 -> 21.25 | AC12: =(AA12-X12)/X12*100 -> 64.589666 | AD12: 60.02 | AE12: =AD12-AA12 -> 5.87 | AF12: =(AD12-AA12)/AA12*100 -> 10.840259 | AG12: 60.34 | AH12: =AG12-AD12 -> 0.32 | AI12: =(AG12-AD12)/AD12*100 -> 0.53315561
A17: Horizontal Analysis - Balance Sheet
A20: Particulars | B20: 42064 | C20: 42430 | D20: Change | E20: %Change | F20: 42795 | G20: Change | H20: %Change | I20: 43160 | J20: Change | K20: %Change | L20: 43525 | M20: Change | N20: %Change | O20: 43891 | P20: Change | Q20: %Change | R20: 44256 | S20: Change | T20: %Change | U20: 44621 | V20: Change | W20: %Change | X20: 44986 | Y20: Change | Z20: %Change | AA20: 45352 | AB20: Change | AC20: %Change | AD20: 45717 | AE20: Change | AF20: %Change | AG20: 46082 | AH20: Change | AI20: %Change
A21: Equity Capital | B21: 29 | C21: 59 | D21: =C21-B21 -> 30 | E21: =(C21-B21)/B21*100 -> 103.44828 | F21: 59 | G21: =F21-C21 -> 0 | H21: =(F21-C21)/C21*100 -> 0 | I21: 59 | J21: =I21-F21 -> 0 | K21: =(I21-F21)/F21*100 -> 0 | L21: 59 | M21: =L21-I21 -> 0 | N21: =(L21-I21)/I21*100 -> 0 | O21: 59 | P21: =O21-L21 -> 0 | Q21: =(O21-L21)/L21*100 -> 0 | R21: 59 | S21: =R21-O21 -> 0 | T21: =(R21-O21)/O21*100 -> 0 | U21: 59 | V21: =U21-R21 -> 0 | W21: =(U21-R21)/R21*100 -> 0 | X21: 59 | Y21: =X21-U21 -> 0 | Z21: =(X21-U21)/U21*100 -> 0 | AA21: 59 | AB21: =AA21-X21 -> 0 | AC21: =(AA21-X21)/X21*100 -> 0 | AD21: 58 | AE21: =AD21-AA21 -> -1 | AF21: =(AD21-AA21)/AA21*100 -> -1.6949153 | AG21: 58 | AH21: =AG21-AD21 -> 0 | AI21: =(AG21-AD21)/AD21*100 -> 0
A22: Reserves | B22: 5127 | C22: 7229 | D22: =C22-B22 -> 2102 | E22: =(C22-B22)/B22*100 -> 40.998635 | F22: 9313 | G22: =F22-C22 -> 2084 | H22: =(F22-C22)/C22*100 -> 28.82833 | I22: 11622 | J22: =I22-F22 -> 2309 | K22: =(I22-F22)/F22*100 -> 24.7933 | L22: 13832 | M22: =L22-I22 -> 2210 | N22: =(L22-I22)/I22*100 -> 19.01566 | O22: 16766 | P22: =O22-L22 -> 2934 | Q22: =(O22-L22)/L22*100 -> 21.211683 | R22: 21871 | S22: =R22-O22 -> 5105 | T22: =(R22-O22)/O22*100 -> 30.448527 | U22: 24517 | V22: =U22-R22 -> 2646 | W22: =(U22-R22)/R22*100 -> 12.098212 | X22: 26781 | Y22: =X22-U22 -> 2264 | Z22: =(X22-U22)/U22*100 -> 9.2344088 | AA22: 29784 | AB22: =AA22-X22 -> 3003 | AC22: =(AA22-X22)/X22*100 -> 11.213174 | AD22: 32595 | AE22: =AD22-AA22 -> 2811 | AF22: =(AD22-AA22)/AA22*100 -> 9.4379533 | AG22: 37833 | AH22: =AG22-AD22 -> 5238 | AI22: =(AG22-AD22)/AD22*100 -> 16.069949
A23: Borrowings | B23: 4451 | C23: 5041 | D23: =C23-B23 -> 590 | E23: =(C23-B23)/B23*100 -> 13.255448 | F23: 3364 | G23: =F23-C23 -> -1677 | H23: =(F23-C23)/C23*100 -> -33.267209 | I23: 4770 | J23: =I23-F23 -> 1406 | K23: =(I23-F23)/F23*100 -> 41.795482 | L23: 6967 | M23: =L23-I23 -> 2197 | N23: =(L23-I23)/I23*100 -> 46.0587 | O23: 5826 | P23: =O23-L23 -> -1141 | Q23: =(O23-L23)/L23*100 -> -16.377207 | R23: 5339 | S23: =R23-O23 -> -487 | T23: =(R23-O23)/O23*100 -> -8.35908 | U23: 2851 | V23: =U23-R23 -> -2488 | W23: =(U23-R23)/R23*100 -> -46.600487 | X23: 5286 | Y23: =X23-U23 -> 2435 | Z23: =(X23-U23)/U23*100 -> 85.408629 | AA23: 6648 | AB23: =AA23-X23 -> 1362 | AC23: =(AA23-X23)/X23*100 -> 25.766175 | AD23: 8263 | AE23: =AD23-AA23 -> 1615 | AF23: =(AD23-AA23)/AA23*100 -> 24.29302 | AG23: 8073 | AH23: =AG23-AD23 -> -190 | AI23: =(AG23-AD23)/AD23*100 -> -2.299407
A24: Other Liabilities | B24: 3303 | C24: 3568 | D24: =C24-B24 -> 265 | E24: =(C24-B24)/B24*100 -> 8.0230094 | F24: 3464 | G24: =F24-C24 -> -104 | H24: =(F24-C24)/C24*100 -> -2.9147982 | I24: 4492 | J24: =I24-F24 -> 1028 | K24: =(I24-F24)/F24*100 -> 29.676674 | L24: 5414 | M24: =L24-I24 -> 922 | N24: =(L24-I24)/I24*100 -> 20.525378 | O24: 6113 | P24: =O24-L24 -> 699 | Q24: =(O24-L24)/L24*100 -> 12.910972 | R24: 6147 | S24: =R24-O24 -> 34 | T24: =(R24-O24)/O24*100 -> 0.55619172 | U24: 6211 | V24: =U24-R24 -> 64 | W24: =(U24-R24)/R24*100 -> 1.0411583 | X24: 7379 | Y24: =X24-U24 -> 1168 | Z24: =(X24-U24)/U24*100 -> 18.805345 | AA24: 8227 | AB24: =AA24-X24 -> 848 | AC24: =(AA24-X24)/X24*100 -> 11.492072 | AD24: 8566 | AE24: =AD24-AA24 -> 339 | AF24: =(AD24-AA24)/AA24*100 -> 4.1205786 | AG24: 12232 | AH24: =AG24-AD24 -> 3666 | AI24: =(AG24-AD24)/AD24*100 -> 42.797105
A25: Total Liabilities&Equity | B25: 12910 | C25: 15896 | D25: =C25-B25 -> 2986 | E25: =(C25-B25)/B25*100 -> 23.129357 | F25: 16200 | G25: =F25-C25 -> 304 | H25: =(F25-C25)/C25*100 -> 1.9124308 | I25: 20942 | J25: =I25-F25 -> 4742 | K25: =(I25-F25)/F25*100 -> 29.271605 | L25: 26271 | M25: =L25-I25 -> 5329 | N25: =(L25-I25)/I25*100 -> 25.446471 | O25: 28765 | P25: =O25-L25 -> 2494 | Q25: =(O25-L25)/L25*100 -> 9.4933577 | R25: 33416 | S25: =R25-O25 -> 4651 | T25: =(R25-O25)/O25*100 -> 16.168955 | U25: 33638 | V25: =U25-R25 -> 222 | W25: =(U25-R25)/R25*100 -> 0.66435241 | X25: 39505 | Y25: =X25-U25 -> 5867 | Z25: =(X25-U25)/U25*100 -> 17.441584 | AA25: 44717 | AB25: =AA25-X25 -> 5212 | AC25: =(AA25-X25)/X25*100 -> 13.193267 | AD25: 49482 | AE25: =AD25-AA25 -> 4765 | AF25: =(AD25-AA25)/AA25*100 -> 10.655903 | AG25: 58196 | AH25: =AG25-AD25 -> 8714 | AI25: =(AG25-AD25)/AD25*100 -> 17.610444
A26: Fixed Assets | B26: 3706 | C26: 4180 | D26: =C26-B26 -> 474 | E26: =(C26-B26)/B26*100 -> 12.79007 | F26: 4834 | G26: =F26-C26 -> 654 | H26: =(F26-C26)/C26*100 -> 15.645933 | I26: 6521 | J26: =I26-F26 -> 1687 | K26: =(I26-F26)/F26*100 -> 34.898635 | L26: 8475 | M26: =L26-I26 -> 1954 | N26: =(L26-I26)/I26*100 -> 29.964729 | O26: 9396 | P26: =O26-L26 -> 921 | Q26: =(O26-L26)/L26*100 -> 10.867257 | R26: 9374 | S26: =R26-O26 -> -22 | T26: =(R26-O26)/O26*100 -> -0.23414219 | U26: 10532 | V26: =U26-R26 -> 1158 | W26: =(U26-R26)/R26*100 -> 12.353318 | X26: 11024 | Y26: =X26-U26 -> 492 | Z26: =(X26-U26)/U26*100 -> 4.6714774 | AA26: 14493 | AB26: =AA26-X26 -> 3469 | AC26: =(AA26-X26)/X26*100 -> 31.467707 | AD26: 14794 | AE26: =AD26-AA26 -> 301 | AF26: =(AD26-AA26)/AA26*100 -> 2.0768647 | AG26: 17407 | AH26: =AG26-AD26 -> 2613 | AI26: =(AG26-AD26)/AD26*100 -> 17.662566
A27: Intangible Assets | B27: 1034 | C27: 844 | D27: =C27-B27 -> -190 | E27: =(C27-B27)/B27*100 -> -18.375242 | F27: 836 | G27: =F27-C27 -> -8 | H27: =(F27-C27)/C27*100 -> -0.9478673 | I27: 1974 | J27: =I27-F27 -> 1138 | K27: =(I27-F27)/F27*100 -> 136.1244 | L27: 3069 | M27: =L27-I27 -> 1095 | N27: =(L27-I27)/I27*100 -> 55.471125 | O27: 3464 | P27: =O27-L27 -> 395 | Q27: =(O27-L27)/L27*100 -> 12.870642 | R27: 3581 | S27: =R27-O27 -> 117 | T27: =(R27-O27)/O27*100 -> 3.3775982 | U27: 3928 | V27: =U27-R27 -> 347 | W27: =(U27-R27)/R27*100 -> 9.6900307 | X27: 5039 | Y27: =X27-U27 -> 1111 | Z27: =(X27-U27)/U27*100 -> 28.284114 | AA27: 5530 | AB27: =AA27-X27 -> 491 | AC27: =(AA27-X27)/X27*100 -> 9.7439968 | AD27: 5735 | AE27: =AD27-AA27 -> 205 | AF27: =(AD27-AA27)/AA27*100 -> 3.7070524 | AG27: 7017 | AH27: =AG27-AD27 -> 1282 | AI27: =(AG27-AD27)/AD27*100 -> 22.353967
A28: CWIP | B28: 420 | C28: 848 | D28: =C28-B28 -> 428 | E28: =(C28-B28)/B28*100 -> 101.90476 | F28: 1458 | G28: =F28-C28 -> 610 | H28: =(F28-C28)/C28*100 -> 71.933962 | I28: 1583 | J28: =I28-F28 -> 125 | K28: =(I28-F28)/F28*100 -> 8.5733882 | L28: 1668 | M28: =L28-I28 -> 85 | N28: =(L28-I28)/I28*100 -> 5.3695515 | O28: 1986 | P28: =O28-L28 -> 318 | Q28: =(O28-L28)/L28*100 -> 19.064748 | R28: 3062 | S28: =R28-O28 -> 1076 | T28: =(R28-O28)/O28*100 -> 54.179255 | U28: 3747 | V28: =U28-R28 -> 685 | W28: =(U28-R28)/R28*100 -> 22.370999 | X28: 5390 | Y28: =X28-U28 -> 1643 | Z28: =(X28-U28)/U28*100 -> 43.848412 | AA28: 3869 | AB28: =AA28-X28 -> -1521 | AC28: =(AA28-X28)/X28*100 -> -28.218924 | AD28: 4900 | AE28: =AD28-AA28 -> 1031 | AF28: =(AD28-AA28)/AA28*100 -> 26.647713 | AG28: 5214 | AH28: =AG28-AD28 -> 314 | AI28: =(AG28-AD28)/AD28*100 -> 6.4081633
A29: Investments | B29: 20 | C29: 123 | D29: =C29-B29 -> 103 | E29: =(C29-B29)/B29*100 -> 515 | F29: 246 | G29: =F29-C29 -> 123 | H29: =(F29-C29)/C29*100 -> 100 | I29: 312 | J29: =I29-F29 -> 66 | K29: =(I29-F29)/F29*100 -> 26.829268 | L29: 360 | M29: =L29-I29 -> 48 | N29: =(L29-I29)/I29*100 -> 15.384615 | O29: 555 | P29: =O29-L29 -> 195 | Q29: =(O29-L29)/L29*100 -> 54.166667 | R29: 591 | S29: =R29-O29 -> 36 | T29: =(R29-O29)/O29*100 -> 6.4864865 | U29: 997 | V29: =U29-R29 -> 406 | W29: =(U29-R29)/R29*100 -> 68.697124 | X29: 543 | Y29: =X29-U29 -> -454 | Z29: =(X29-U29)/U29*100 -> -45.53661 | AA29: 372 | AB29: =AA29-X29 -> -171 | AC29: =(AA29-X29)/X29*100 -> -31.491713 | AD29: 252 | AE29: =AD29-AA29 -> -120 | AF29: =(AD29-AA29)/AA29*100 -> -32.258065 | AG29: 1051 | AH29: =AG29-AD29 -> 799 | AI29: =(AG29-AD29)/AD29*100 -> 317.06349
A30: Other Assets | B30: 8765 | C30: 10745 | D30: =C30-B30 -> 1980 | E30: =(C30-B30)/B30*100 -> 22.589846 | F30: 9662 | G30: =F30-C30 -> -1083 | H30: =(F30-C30)/C30*100 -> -10.079107 | I30: 12527 | J30: =I30-F30 -> 2865 | K30: =(I30-F30)/F30*100 -> 29.652246 | L30: 15768 | M30: =L30-I30 -> 3241 | N30: =(L30-I30)/I30*100 -> 25.872116 | O30: 16827 | P30: =O30-L30 -> 1059 | Q30: =(O30-L30)/L30*100 -> 6.7161339 | R30: 20390 | S30: =R30-O30 -> 3563 | T30: =(R30-O30)/O30*100 -> 21.174303 | U30: 18362 | V30: =U30-R30 -> -2028 | W30: =(U30-R30)/R30*100 -> -9.946052 | X30: 22549 | Y30: =X30-U30 -> 4187 | Z30: =(X30-U30)/U30*100 -> 22.802527 | AA30: 25983 | AB30: =AA30-X30 -> 3434 | AC30: =(AA30-X30)/X30*100 -> 15.229057 | AD30: 29536 | AE30: =AD30-AA30 -> 3553 | AF30: =(AD30-AA30)/AA30*100 -> 13.674326 | AG30: 34525 | AH30: =AG30-AD30 -> 4989 | AI30: =(AG30-AD30)/AD30*100 -> 16.891251
A31: Inventories | B31: 3611 | C31: 4056 | D31: =C31-B31 -> 445 | E31: =(C31-B31)/B31*100 -> 12.323456 | F31: 4331 | G31: =F31-C31 -> 275 | H31: =(F31-C31)/C31*100 -> 6.7800789 | I31: 5858 | J31: =I31-F31 -> 1527 | K31: =(I31-F31)/F31*100 -> 35.257446 | L31: 7246 | M31: =L31-I31 -> 1388 | N31: =(L31-I31)/I31*100 -> 23.694094 | O31: 7700 | P31: =O31-L31 -> 454 | Q31: =(O31-L31)/L31*100 -> 6.2655258 | R31: 9041 | S31: =R31-O31 -> 1341 | T31: =(R31-O31)/O31*100 -> 17.415584 | U31: 7559 | V31: =U31-R31 -> -1482 | W31: =(U31-R31)/R31*100 -> -16.391992 | X31: 8516 | Y31: =X31-U31 -> 957 | Z31: =(X31-U31)/U31*100 -> 12.660405 | AA31: 9810 | AB31: =AA31-X31 -> 1294 | AC31: =(AA31-X31)/X31*100 -> 15.194927 | AD31: 10544 | AE31: =AD31-AA31 -> 734 | AF31: =(AD31-AA31)/AA31*100 -> 7.4821611 | AG31: 12053 | AH31: =AG31-AD31 -> 1509 | AI31: =(AG31-AD31)/AD31*100 -> 14.311457
A32: Trade Receivables | B32: 3539 | C32: 4607 | D32: =C32-B32 -> 1068 | E32: =(C32-B32)/B32*100 -> 30.178016 | F32: 2765 | G32: =F32-C32 -> -1842 | H32: =(F32-C32)/C32*100 -> -39.982635 | I32: 3080 | J32: =I32-F32 -> 315 | K32: =(I32-F32)/F32*100 -> 11.392405 | L32: 3414 | M32: =L32-I32 -> 334 | N32: =(L32-I32)/I32*100 -> 10.844156 | O32: 4315 | P32: =O32-L32 -> 901 | Q32: =(O32-L32)/L32*100 -> 26.39133 | R32: 3503 | S32: =R32-O32 -> -812 | T32: =(R32-O32)/O32*100 -> -18.818076 | U32: 4012 | V32: =U32-R32 -> 509 | W32: =(U32-R32)/R32*100 -> 14.530403 | X32: 4466 | Y32: =X32-U32 -> 454 | Z32: =(X32-U32)/U32*100 -> 11.316052 | AA32: 4817 | AB32: =AA32-X32 -> 351 | AC32: =(AA32-X32)/X32*100 -> 7.859382 | AD32: 5746 | AE32: =AD32-AA32 -> 929 | AF32: =(AD32-AA32)/AA32*100 -> 19.285863 | AG32: 7094 | AH32: =AG32-AD32 -> 1348 | AI32: =(AG32-AD32)/AD32*100 -> 23.459798
... A34: Total Assets | B34: 12910 | C34: 15896 | D34: =C34-B34 -> 2986 | E34: =(C34-B34)/B34*100 -> 23.129357 | F34: 16200 | G34: =F34-C34 -> 304 | H34: =(F34-C34)/C34*100 -> 1.9124308 | I34: 20942 | J34: =I34-F34 -> 4742 | K34: =(I34-F34)/F34*100 -> 29.271605 | L34: 26271 | M34: =L34-I34 -> 5329 | N34: =(L34-I34)/I34*100 -> 25.446471 | O34: 28765 | P34: =O34-L34 -> 2494 | Q34: =(O34-L34)/L34*100 -> 9.4933577 | R34: 33416 | S34: =R34-O34 -> 4651 | T34: =(R34-O34)/O34*100 -> 16.168955 | U34: 33638 | V34: =U34-R34 -> 222 | W34: =(U34-R34)/R34*100 -> 0.66435241 | X34: 39505 | Y34: =X34-U34 -> 5867 | Z34: =(X34-U34)/U34*100 -> 17.441584 | AA34: 44717 | AB34: =AA34-X34 -> 5212 | AC34: =(AA34-X34)/X34*100 -> 13.193267 | AD34: 49482 | AE34: =AD34-AA34 -> 4765 | AF34: =(AD34-AA34)/AA34*100 -> 10.655903 | AG34: 58196 | AH34: =AG34-AD34 -> 8714 | AI34: =(AG34-AD34)/AD34*100 -> 17.610444

Sheet Vertical Analysis
A1: Vertical Analysis - Income Statement
A4: Particulars | B4: 42064 | C4: 42430 | D4: 42795 | E4: 43160 | F4: 43525 | G4: 43891 | H4: 44256 | I4: 44621 | J4: 44986 | K4: 45352 | L4: 45717 | M4: 46082
A5: Sales | B5: 1 | C5: 1 | D5: 1 | E5: 1 | F5: 1 | G5: 1 | H5: 1 | I5: 1 | J5: 1 | K5: 1 | L5: 1 | M5: 1
A6: Expenses | B6: ='Income Statement'!B4/'Income Statement'!B2 -> 0.78691234 | C6: ='Income Statement'!C4/'Income Statement'!C2 -> 0.76815277 | D6: ='Income Statement'!D4/'Income Statement'!D2 -> 0.76921529 | E6: ='Income Statement'!E4/'Income Statement'!E2 -> 0.77088016 | F6: ='Income Statement'!F4/'Income Statement'!F2 -> 0.79799632 | G6: ='Income Statement'!G4/'Income Statement'!G2 -> 0.7900342 | H6: ='Income Statement'!H4/'Income Statement'!H2 -> 0.78696266 | I6: ='Income Statement'!I4/'Income Statement'!I2 -> 0.81261991 | ... M6: ='Income Statement'!M4/'Income Statement'!M2 -> 0.79585772
A7: Operating Profit | B7: ='Income Statement'!B11/'Income Statement'!B2 -> 0.21308766 | C7: ='Income Statement'!C11/'Income Statement'!C2 -> 0.23184723 | D7: ='Income Statement'!D11/'Income Statement'!D2 -> 0.23078471 | E7: ='Income Statement'!E11/'Income Statement'!E2 -> 0.22911984 | F7: ='Income Statement'!F11/'Income Statement'!F2 -> 0.20200368 | G7: ='Income Statement'!G11/'Income Statement'!G2 -> 0.20992251 | H7: ='Income Statement'!H11/'Income Statement'!H2 -> 0.21303734 | I7: ='Income Statement'!I11/'Income Statement'!I2 -> 0.18742272 | ... M7: ='Income Statement'!M11/'Income Statement'!M2 -> 0.20414228
A8: Other Income | B8: ='Income Statement'!B13/'Income Statement'!B2 -> 0.0066925556 | C8: ='Income Statement'!C13/'Income Statement'!C2 -> 0.014522219 | D8: ='Income Statement'!D13/'Income Statement'!D2 -> 0.0077129443 | E8: ='Income Statement'!E13/'Income Statement'!E2 -> 0.0063779384 | F8: ='Income Statement'!F13/'Income Statement'!F2 -> 0.0035780004 | G8: ='Income Statement'!G13/'Income Statement'!G2 -> 0.0071864583 | H8: ='Income Statement'!H13/'Income Statement'!H2 -> 0.12896065 | I8: ='Income Statement'!I13/'Income Statement'!I2 -> 0.0064804946 | ... M8: ='Income Statement'!M13/'Income Statement'!M2 -> 0.012004873
A9: Interest | B9: ='Income Statement'!B16/'Income Statement'!B2 -> 0.013219863 | C9: ='Income Statement'!C16/'Income Statement'!C2 -> 0.018661051 | D9: ='Income Statement'!D16/'Income Statement'!D2 -> 0.0044936284 | E9: ='Income Statement'!E16/'Income Statement'!E2 -> 0.0047378971 | F9: ='Income Statement'!F16/'Income Statement'!F2 -> 0.013443059 | G9: ='Income Statement'!G16/'Income Statement'!G2 -> 0.013204035 | H9: ='Income Statement'!H16/'Income Statement'!H2 -> 0.0029868819 | I9: ='Income Statement'!I16/'Income Statement'!I2 -> 0.0020891068 | ... M9: ='Income Statement'!M16/'Income Statement'!M2 -> 0.011410573
A10: Depreciation | B10: ='Income Statement'!B17/'Income Statement'!B2 -> 0.02751384 | C10: ='Income Statement'!C17/'Income Statement'!C2 -> 0.028463549 | D10: ='Income Statement'!D17/'Income Statement'!D2 -> 0.028705567 | E10: ='Income Statement'!E17/'Income Statement'!E2 -> 0.033894187 | F10: ='Income Statement'!F17/'Income Statement'!F2 -> 0.034144347 | G10: ='Income Statement'!G17/'Income Statement'!G2 -> 0.041863284 | H10: ='Income Statement'!H17/'Income Statement'!H2 -> 0.042583249 | I10: ='Income Statement'!I17/'Income Statement'!I2 -> 0.048049456 | ... M10: ='Income Statement'!M17/'Income Statement'!M2 -> 0.052833328
A11: Profit Before Tax | B11: ='Income Statement'!B18/'Income Statement'!B2 -> 0.17912914 | C11: ='Income Statement'!C18/'Income Statement'!C2 -> 0.19924484 | D11: ='Income Statement'!D18/'Income Statement'!D2 -> 0.20529846 | E11: ='Income Statement'!E18/'Income Statement'!E2 -> 0.1968657 | F11: ='Income Statement'!F18/'Income Statement'!F2 -> 0.15799428 | G11: ='Income Statement'!G18/'Income Statement'!G2 -> 0.16204165 | H11: ='Income Statement'!H18/'Income Statement'!H2 -> 0.29642785 | I11: ='Income Statement'!I18/'Income Statement'!I2 -> 0.14380729 | ... M11: ='Income Statement'!M18/'Income Statement'!M2 -> 0.15190325
A12: Net Profit | B12: ='Income Statement'!B20/'Income Statement'!B2 -> 0.12980253 | C12: ='Income Statement'!C20/'Income Statement'!C2 -> 0.14696486 | D12: ='Income Statement'!D20/'Income Statement'!D2 -> 0.15432596 | E12: ='Income Statement'!E20/'Income Statement'!E2 -> 0.14717852 | F12: ='Income Statement'!F20/'Income Statement'!F2 -> 0.12083419 | G12: ='Income Statement'!G20/'Income Statement'!G2 -> 0.12312221 | H12: ='Income Statement'!H20/'Income Statement'!H2 -> 0.21529768 | I12: ='Income Statement'!I20/'Income Statement'!I2 -> 0.1128544 | ... M12: ='Income Statement'!M20/'Income Statement'!M2 -> 0.10409176
A14: Vertical Analysis - Balance Sheet
A18: Particulars | B18: 42064 | C18: 42430 | D18: 42795 | E18: 43160 | F18: 43525 | G18: 43891 | H18: 44256 | I18: 44621 | J18: 44986 | K18: 45352 | L18: 45717 | M18: 46082
A19: Equity Capital | B19: ='Balance Sheet'!B2/'Balance Sheet'!B35 -> 0.0022463207 | C19: ='Balance Sheet'!C2/'Balance Sheet'!C35 -> 0.0037116256 | D19: ='Balance Sheet'!D2/'Balance Sheet'!D35 -> 0.0036419753 | E19: ='Balance Sheet'!E2/'Balance Sheet'!E35 -> 0.0028173049 | F19: ='Balance Sheet'!F2/'Balance Sheet'!F35 -> 0.0022458224 | G19: ='Balance Sheet'!G2/'Balance Sheet'!G35 -> 0.0020511038 | H19: ='Balance Sheet'!H2/'Balance Sheet'!H35 -> 0.0017656213 | I19: ='Balance Sheet'!I2/'Balance Sheet'!I35 -> 0.0017539687 | ... M19: ='Balance Sheet'!M2/'Balance Sheet'!M35 -> 0.00099663207
A20: Reserves | B20: ='Balance Sheet'!B3/'Balance Sheet'!B35 -> 0.397134 | C20: ='Balance Sheet'!C3/'Balance Sheet'!C35 -> 0.4547685 | D20: ='Balance Sheet'!D3/'Balance Sheet'!D35 -> 0.57487654 | E20: ='Balance Sheet'!E3/'Balance Sheet'!E35 -> 0.55496132 | F20: ='Balance Sheet'!F3/'Balance Sheet'!F35 -> 0.52651212 | G20: ='Balance Sheet'!G3/'Balance Sheet'!G35 -> 0.58286112 | H20: ='Balance Sheet'!H3/'Balance Sheet'!H35 -> 0.65450682 | I20: ='Balance Sheet'!I3/'Balance Sheet'!I35 -> 0.72884833 | ... M20: ='Balance Sheet'!M3/'Balance Sheet'!M35 -> 0.65009623
A21: Borrowings | B21: ='Balance Sheet'!B4/'Balance Sheet'!B35 -> 0.34477149 | C21: ='Balance Sheet'!C4/'Balance Sheet'!C35 -> 0.3171238 | D21: ='Balance Sheet'!D4/'Balance Sheet'!D35 -> 0.20765432 | E21: ='Balance Sheet'!E4/'Balance Sheet'!E35 -> 0.22777194 | F21: ='Balance Sheet'!F4/'Balance Sheet'!F35 -> 0.26519737 | G21: ='Balance Sheet'!G4/'Balance Sheet'!G35 -> 0.20253781 | H21: ='Balance Sheet'!H4/'Balance Sheet'!H35 -> 0.15977376 | I21: ='Balance Sheet'!I4/'Balance Sheet'!I35 -> 0.084755336 | ... M21: ='Balance Sheet'!M4/'Balance Sheet'!M35 -> 0.13872087
A22: Other Liabilities | B22: ='Balance Sheet'!B10/'Balance Sheet'!B35 -> 0.25584818 | C22: ='Balance Sheet'!C10/'Balance Sheet'!C35 -> 0.22445898 | D22: ='Balance Sheet'!D10/'Balance Sheet'!D35 -> 0.21382716 | E22: ='Balance Sheet'!E10/'Balance Sheet'!E35 -> 0.21449718 | F22: ='Balance Sheet'!F10/'Balance Sheet'!F35 -> 0.20608275 | G22: ='Balance Sheet'!G10/'Balance Sheet'!G35 -> 0.21251521 | H22: ='Balance Sheet'!H10/'Balance Sheet'!H35 -> 0.18395379 | I22: ='Balance Sheet'!I10/'Balance Sheet'!I35 -> 0.18464237 | ... M22: ='Balance Sheet'!M10/'Balance Sheet'!M35 -> 0.21018627
A23: Total Liabilities&Equity | B23: ='Balance Sheet'!B15/'Balance Sheet'!B35 -> 1 | C23: ='Balance Sheet'!C15/'Balance Sheet'!C35 -> 1 | D23: ='Balance Sheet'!D15/'Balance Sheet'!D35 -> 1 | E23: ='Balance Sheet'!E15/'Balance Sheet'!E35 -> 1 | F23: ='Balance Sheet'!F15/'Balance Sheet'!F35 -> 1 | G23: ='Balance Sheet'!G15/'Balance Sheet'!G35 -> 1 | H23: ='Balance Sheet'!H15/'Balance Sheet'!H35 -> 1 | I23: ='Balance Sheet'!I15/'Balance Sheet'!I35 -> 1 | ... M23: ='Balance Sheet'!M15/'Balance Sheet'!M35 -> 1
A24: Fixed Assets | B24: ='Balance Sheet'!B16/'Balance Sheet'!B35 -> 0.28706429 | C24: ='Balance Sheet'!C16/'Balance Sheet'!C35 -> 0.26295924 | D24: ='Balance Sheet'!D16/'Balance Sheet'!D35 -> 0.29839506 | E24: ='Balance Sheet'!E16/'Balance Sheet'!E35 -> 0.31138382 | F24: ='Balance Sheet'!F16/'Balance Sheet'!F35 -> 0.32259906 | G24: ='Balance Sheet'!G16/'Balance Sheet'!G35 -> 0.32664697 | H24: ='Balance Sheet'!H16/'Balance Sheet'!H35 -> 0.2805243 | I24: ='Balance Sheet'!I16/'Balance Sheet'!I35 -> 0.31309828 | ... M24: ='Balance Sheet'!M16/'Balance Sheet'!M35 -> 0.2991099
A25: Intangible Assets | B25: ='Balance Sheet'!B23/'Balance Sheet'!B35 -> 0.080092951 | C25: ='Balance Sheet'!C23/'Balance Sheet'!C35 -> 0.053095118 | D25: ='Balance Sheet'!D23/'Balance Sheet'!D35 -> 0.051604938 | E25: ='Balance Sheet'!E23/'Balance Sheet'!E35 -> 0.094260338 | F25: ='Balance Sheet'!F23/'Balance Sheet'!F35 -> 0.11682083 | G25: ='Balance Sheet'!G23/'Balance Sheet'!G35 -> 0.12042413 | H25: ='Balance Sheet'!H23/'Balance Sheet'!H35 -> 0.10716423 | I25: ='Balance Sheet'!I23/'Balance Sheet'!I35 -> 0.1167727 | ... M25: ='Balance Sheet'!M23/'Balance Sheet'!M35 -> 0.1205753
A26: CWIP | B26: ='Balance Sheet'!B27/'Balance Sheet'!B35 -> 0.03253292 | C26: ='Balance Sheet'!C27/'Balance Sheet'!C35 -> 0.053346754 | D26: ='Balance Sheet'!D27/'Balance Sheet'!D35 -> 0.09 | E26: ='Balance Sheet'!E27/'Balance Sheet'!E35 -> 0.075589724 | F26: ='Balance Sheet'!F27/'Balance Sheet'!F35 -> 0.063492063 | G26: ='Balance Sheet'!G27/'Balance Sheet'!G35 -> 0.069042239 | H26: ='Balance Sheet'!H27/'Balance Sheet'!H35 -> 0.091632751 | I26: ='Balance Sheet'!I27/'Balance Sheet'!I35 -> 0.11139188 | ... M26: ='Balance Sheet'!M27/'Balance Sheet'!M35 -> 0.089593787
A27: Investments | B27: ='Balance Sheet'!B28/'Balance Sheet'!B35 -> 0.0015491867 | C27: ='Balance Sheet'!C28/'Balance Sheet'!C35 -> 0.0077377957 | D27: ='Balance Sheet'!D28/'Balance Sheet'!D35 -> 0.015185185 | E27: ='Balance Sheet'!E28/'Balance Sheet'!E35 -> 0.014898291 | F27: ='Balance Sheet'!F28/'Balance Sheet'!F35 -> 0.013703323 | G27: ='Balance Sheet'!G28/'Balance Sheet'!G35 -> 0.019294281 | H27: ='Balance Sheet'!H28/'Balance Sheet'!H35 -> 0.017686138 | I27: ='Balance Sheet'!I28/'Balance Sheet'!I35 -> 0.029639099 | ... M27: ='Balance Sheet'!M28/'Balance Sheet'!M35 -> 0.01805966
A28: Other Assets | B28: ='Balance Sheet'!B29/'Balance Sheet'!B35 -> 0.67893106 | C28: ='Balance Sheet'!C29/'Balance Sheet'!C35 -> 0.67595622 | D28: ='Balance Sheet'!D29/'Balance Sheet'!D35 -> 0.59641975 | E28: ='Balance Sheet'!E29/'Balance Sheet'!E35 -> 0.59817591 | F28: ='Balance Sheet'!F29/'Balance Sheet'!F35 -> 0.60020555 | G28: ='Balance Sheet'!G29/'Balance Sheet'!G35 -> 0.58498175 | H28: ='Balance Sheet'!H29/'Balance Sheet'!H35 -> 0.61018674 | I28: ='Balance Sheet'!I29/'Balance Sheet'!I35 -> 0.54587074 | ... M28: ='Balance Sheet'!M29/'Balance Sheet'!M35 -> 0.59325383
A29: Inventories | B29: ='Balance Sheet'!B30/'Balance Sheet'!B35 -> 0.27970565 | C29: ='Balance Sheet'!C30/'Balance Sheet'!C35 -> 0.25515853 | D29: ='Balance Sheet'!D30/'Balance Sheet'!D35 -> 0.26734568 | E29: ='Balance Sheet'!E30/'Balance Sheet'!E35 -> 0.27972495 | F29: ='Balance Sheet'!F30/'Balance Sheet'!F35 -> 0.27581744 | G29: ='Balance Sheet'!G30/'Balance Sheet'!G35 -> 0.26768642 | H29: ='Balance Sheet'!H30/'Balance Sheet'!H35 -> 0.27055901 | I29: ='Balance Sheet'!I30/'Balance Sheet'!I35 -> 0.22471609 | ... M29: ='Balance Sheet'!M30/'Balance Sheet'!M35 -> 0.20711045
A30: Trade Receivables | B30: ='Balance Sheet'!B31/'Balance Sheet'!B35 -> 0.27412858 | C30: ='Balance Sheet'!C31/'Balance Sheet'!C35 -> 0.28982134 | D30: ='Balance Sheet'!D31/'Balance Sheet'!D35 -> 0.17067901 | E30: ='Balance Sheet'!E31/'Balance Sheet'!E35 -> 0.14707287 | F30: ='Balance Sheet'!F31/'Balance Sheet'!F35 -> 0.12995318 | G30: ='Balance Sheet'!G31/'Balance Sheet'!G35 -> 0.15000869 | H30: ='Balance Sheet'!H31/'Balance Sheet'!H35 -> 0.10483002 | I30: ='Balance Sheet'!I31/'Balance Sheet'!I35 -> 0.11926987 | ... M30: ='Balance Sheet'!M31/'Balance Sheet'!M35 -> 0.12189841
A31: Cash Equivalents | B31: ='Balance Sheet'!B32/'Balance Sheet'!B35 -> 0.036328428 | C31: ='Balance Sheet'!C32/'Balance Sheet'!C35 -> 0.050327126 | D31: ='Balance Sheet'!D32/'Balance Sheet'!D35 -> 0.031666667 | E31: ='Balance Sheet'!E32/'Balance Sheet'!E35 -> 0.060261675 | F31: ='Balance Sheet'!F32/'Balance Sheet'!F35 -> 0.074492787 | G31: ='Balance Sheet'!G32/'Balance Sheet'!G35 -> 0.098800626 | H31: ='Balance Sheet'!H32/'Balance Sheet'!H35 -> 0.16381374 | I31: ='Balance Sheet'!I32/'Balance Sheet'!I35 -> 0.12456151 | ... M31: ='Balance Sheet'!M32/'Balance Sheet'!M35 -> 0.16959929
A32: Total Assets | B32: 1 | C32: 1 | D32: 1 | E32: 1 | F32: 1 | G32: 1 | H32: 1 | I32: 1 | J32: 1 | K32: 1 | L32: 1 | M32: 1

Sheet Trend Analysis
A2: Trend Analysis - Income Statement
A5: Particulars | B5: 42064 | C5: 42430 | D5: 42795 | E5: 43160 | F5: 43525 | G5: 43891 | H5: 44256 | I5: 44621 | J5: 44986 | K5: 45352 | L5: 45717 | M5: 46082
A6: Sales | B6: 100 | C6: ='Income Statement'!C2/'Income Statement'!$B2*100 -> 113.78997 | D6: ='Income Statement'!D2/'Income Statement'!$B2*100 -> 123.1926 | E6: ='Income Statement'!E2/'Income Statement'!$B2*100 -> 136.02413 | F6: ='Income Statement'!F2/'Income Statement'!$B2*100 -> 161.64587 | G6: ='Income Statement'!G2/'Income Statement'!$B2*100 -> 190.85351 | H6: ='Income Statement'!H2/'Income Statement'!$B2*100 -> 204.70131 | I6: ='Income Statement'!I2/'Income Statement'!$B2*100 -> 193.79493 | J6: ='Income Statement'!J2/'Income Statement'!$B2*100 -> 205.36231 | ... M6: ='Income Statement'!M2/'Income Statement'!$B2*100 -> 278.05503
A7: Expenses | B7: 100 | C7: ='Income Statement'!C4/'Income Statement'!$B4*100 -> 111.07728 | D7: ='Income Statement'!D4/'Income Statement'!$B4*100 -> 120.42209 | E7: ='Income Statement'!E4/'Income Statement'!$B4*100 -> 133.25283 | F7: ='Income Statement'!F4/'Income Statement'!$B4*100 -> 163.92272 | G7: ='Income Statement'!G4/'Income Statement'!$B4*100 -> 191.61067 | H7: ='Income Statement'!H4/'Income Statement'!$B4*100 -> 204.71441 | I7: ='Income Statement'!I4/'Income Statement'!$B4*100 -> 200.126 | J7: ='Income Statement'!J4/'Income Statement'!$B4*100 -> 222.04956 | ... M7: ='Income Statement'!M4/'Income Statement'!$B4*100 -> 281.21588
A8: Operating Profit | B8: 100 | C8: ='Income Statement'!C11/'Income Statement'!$B11*100 -> 123.80768 | D8: ='Income Statement'!D11/'Income Statement'!$B11*100 -> 133.42381 | E8: ='Income Statement'!E11/'Income Statement'!$B11*100 -> 146.25824 | F8: ='Income Statement'!F11/'Income Statement'!$B11*100 -> 153.23769 | G8: ='Income Statement'!G11/'Income Statement'!$B11*100 -> 188.01861 | H8: ='Income Statement'!H11/'Income Statement'!$B11*100 -> 204.65297 | I8: ='Income Statement'!I11/'Income Statement'!$B11*100 -> 170.45366 | J8: ='Income Statement'!J11/'Income Statement'!$B11*100 -> 143.73788 | ... M8: ='Income Statement'!M11/'Income Statement'!$B11*100 -> 266.38232
A9: Other Income | B9: 100 | C9: ='Income Statement'!C13/'Income Statement'!$B13*100 -> 246.91358 | D9: ='Income Statement'!D13/'Income Statement'!$B13*100 -> 141.97531 | E9: ='Income Statement'!E13/'Income Statement'!$B13*100 -> 129.62963 | F9: ='Income Statement'!F13/'Income Statement'!$B13*100 -> 86.419753 | G9: ='Income Statement'!G13/'Income Statement'!$B13*100 -> 204.93827 | H9: ='Income Statement'!H13/'Income Statement'!$B13*100 -> 3944.4444 | I9: ='Income Statement'!I13/'Income Statement'!$B13*100 -> 187.65432 | J9: ='Income Statement'!J13/'Income Statement'!$B13*100 -> 359.25926 | ... M9: ='Income Statement'!M13/'Income Statement'!$B13*100 -> 498.76543
A10: Interest | B10: 100 | C10: ='Income Statement'!C16/'Income Statement'!$B16*100 -> 160.625 | D10: ='Income Statement'!D16/'Income Statement'!$B16*100 -> 41.875 | E10: ='Income Statement'!E16/'Income Statement'!$B16*100 -> 48.75 | F10: ='Income Statement'!F16/'Income Statement'!$B16*100 -> 164.375 | G10: ='Income Statement'!G16/'Income Statement'!$B16*100 -> 190.625 | H10: ='Income Statement'!H16/'Income Statement'!$B16*100 -> 46.25 | I10: ='Income Statement'!I16/'Income Statement'!$B16*100 -> 30.625 | J10: ='Income Statement'!J16/'Income Statement'!$B16*100 -> 87.5 | ... M10: ='Income Statement'!M16/'Income Statement'!$B16*100 -> 240
A11: Depreciation | B11: 100 | C11: ='Income Statement'!C17/'Income Statement'!$B17*100 -> 117.71772 | D11: ='Income Statement'!D17/'Income Statement'!$B17*100 -> 128.52853 | E11: ='Income Statement'!E17/'Income Statement'!$B17*100 -> 167.56757 | F11: ='Income Statement'!F17/'Income Statement'!$B17*100 -> 200.6006 | G11: ='Income Statement'!G17/'Income Statement'!$B17*100 -> 290.39039 | H11: ='Income Statement'!H17/'Income Statement'!$B17*100 -> 316.81682 | I11: ='Income Statement'!I17/'Income Statement'!$B17*100 -> 338.43844 | J11: ='Income Statement'!J17/'Income Statement'!$B17*100 -> 373.87387 | ... M11: ='Income Statement'!M17/'Income Statement'!$B17*100 -> 533.93393
A12: Profit Before Tax | B12: 100 | C12: ='Income Statement'!C18/'Income Statement'!$B18*100 -> 126.56827 | D12: ='Income Statement'!D18/'Income Statement'!$B18*100 -> 141.19004 | E12: ='Income Statement'!E18/'Income Statement'!$B18*100 -> 149.49262 | F12: ='Income Statement'!F18/'Income Statement'!$B18*100 -> 142.5738 | G12: ='Income Statement'!G18/'Income Statement'!$B18*100 -> 172.6476 | H12: ='Income Statement'!H18/'Income Statement'!$B18*100 -> 338.74539 | I12: ='Income Statement'!I18/'Income Statement'!$B18*100 -> 155.58118 | J12: ='Income Statement'!J18/'Income Statement'!$B18*100 -> 120.4797 | ... M12: ='Income Statement'!M18/'Income Statement'!$B18*100 -> 235.79336
A13: Net Profit | B13: 100 | C13: ='Income Statement'!C20/'Income Statement'!$B20*100 -> 128.83514 | D13: ='Income Statement'!D20/'Income Statement'!$B20*100 -> 146.46722 | E13: ='Income Statement'!E20/'Income Statement'!$B20*100 -> 154.23297 | F13: ='Income Statement'!F20/'Income Statement'!$B20*100 -> 150.4774 | G13: ='Income Statement'!G20/'Income Statement'!$B20*100 -> 181.03119 | H13: ='Income Statement'!H20/'Income Statement'!$B20*100 -> 339.52896 | I13: ='Income Statement'!I20/'Income Statement'!$B20*100 -> 168.49141 | J13: ='Income Statement'!J20/'Income Statement'!$B20*100 -> 122.72438 | ... M13: ='Income Statement'!M20/'Income Statement'!$B20*100 -> 222.97899
A14: EPS | B14: 100 | C14: ='Income Statement'!C27/'Income Statement'!$B27*100 -> 128.28021 | D14: ='Income Statement'!D27/'Income Statement'!$B27*100 -> 145.62639 | E14: ='Income Statement'!E27/'Income Statement'!$B27*100 -> 153.29874 | F14: ='Income Statement'!F27/'Income Statement'!$B27*100 -> 149.59229 | G14: ='Income Statement'!G27/'Income Statement'!$B27*100 -> 179.98517 | H14: ='Income Statement'!H27/'Income Statement'!$B27*100 -> 337.4722 | I14: ='Income Statement'!I27/'Income Statement'!$B27*100 -> 167.5315 | J14: ='Income Statement'!J27/'Income Statement'!$B27*100 -> 121.94218 | ... M14: ='Income Statement'!M27/'Income Statement'!$B27*100 -> 223.64715
A16: Trend Analysis - Balance Sheet
A19: Particulars | B19: 42064 | C19: 42430 | D19: 42795 | E19: 43160 | F19: 43525 | G19: 43891 | H19: 44256 | I19: 44621 | J19: 44986 | K19: 45352 | L19: 45717 | M19: 46082
A20: Equity Capital | B20: 100 | C20: ='Balance Sheet'!C2/'Balance Sheet'!$B2*100 -> 203.44828 | D20: ='Balance Sheet'!D2/'Balance Sheet'!$B2*100 -> 203.44828 | E20: ='Balance Sheet'!E2/'Balance Sheet'!$B2*100 -> 203.44828 | F20: ='Balance Sheet'!F2/'Balance Sheet'!$B2*100 -> 203.44828 | G20: ='Balance Sheet'!G2/'Balance Sheet'!$B2*100 -> 203.44828 | H20: ='Balance Sheet'!H2/'Balance Sheet'!$B2*100 -> 203.44828 | I20: ='Balance Sheet'!I2/'Balance Sheet'!$B2*100 -> 203.44828 | J20: ='Balance Sheet'!J2/'Balance Sheet'!$B2*100 -> 203.44828 | ... M20: ='Balance Sheet'!M2/'Balance Sheet'!$B2*100 -> 200
A21: Reserves | B21: 100 | C21: ='Balance Sheet'!C3/'Balance Sheet'!$B3*100 -> 140.99863 | D21: ='Balance Sheet'!D3/'Balance Sheet'!$B3*100 -> 181.64619 | E21: ='Balance Sheet'!E3/'Balance Sheet'!$B3*100 -> 226.68227 | F21: ='Balance Sheet'!F3/'Balance Sheet'!$B3*100 -> 269.7874 | G21: ='Balance Sheet'!G3/'Balance Sheet'!$B3*100 -> 327.01385 | H21: ='Balance Sheet'!H3/'Balance Sheet'!$B3*100 -> 426.58475 | I21: ='Balance Sheet'!I3/'Balance Sheet'!$B3*100 -> 478.19388 | J21: ='Balance Sheet'!J3/'Balance Sheet'!$B3*100 -> 522.35225 | ... M21: ='Balance Sheet'!M3/'Balance Sheet'!$B3*100 -> 737.91691
A22: Borrowings | B22: 100 | C22: ='Balance Sheet'!C4/'Balance Sheet'!$B4*100 -> 113.25545 | D22: ='Balance Sheet'!D4/'Balance Sheet'!$B4*100 -> 75.578522 | E22: ='Balance Sheet'!E4/'Balance Sheet'!$B4*100 -> 107.16693 | F22: ='Balance Sheet'!F4/'Balance Sheet'!$B4*100 -> 156.52662 | G22: ='Balance Sheet'!G4/'Balance Sheet'!$B4*100 -> 130.89193 | H22: ='Balance Sheet'!H4/'Balance Sheet'!$B4*100 -> 119.95057 | I22: ='Balance Sheet'!I4/'Balance Sheet'!$B4*100 -> 64.053022 | J22: ='Balance Sheet'!J4/'Balance Sheet'!$B4*100 -> 118.75983 | ... M22: ='Balance Sheet'!M4/'Balance Sheet'!$B4*100 -> 181.37497
A23: Other Liabilities | B23: 100 | C23: ='Balance Sheet'!C10/'Balance Sheet'!$B10*100 -> 108.02301 | D23: ='Balance Sheet'!D10/'Balance Sheet'!$B10*100 -> 104.87436 | E23: ='Balance Sheet'!E10/'Balance Sheet'!$B10*100 -> 135.99758 | F23: ='Balance Sheet'!F10/'Balance Sheet'!$B10*100 -> 163.9116 | G23: ='Balance Sheet'!G10/'Balance Sheet'!$B10*100 -> 185.07417 | H23: ='Balance Sheet'!H10/'Balance Sheet'!$B10*100 -> 186.10354 | I23: ='Balance Sheet'!I10/'Balance Sheet'!$B10*100 -> 188.04117 | J23: ='Balance Sheet'!J10/'Balance Sheet'!$B10*100 -> 223.40297 | ... M23: ='Balance Sheet'!M10/'Balance Sheet'!$B10*100 -> 370.33
A24: Total Liabilities&Equity | B24: 100 | C24: ='Balance Sheet'!C15/'Balance Sheet'!$B15*100 -> 123.12936 | D24: ='Balance Sheet'!D15/'Balance Sheet'!$B15*100 -> 125.48412 | E24: ='Balance Sheet'!E15/'Balance Sheet'!$B15*100 -> 162.21534 | F24: ='Balance Sheet'!F15/'Balance Sheet'!$B15*100 -> 203.49342 | G24: ='Balance Sheet'!G15/'Balance Sheet'!$B15*100 -> 222.81177 | H24: ='Balance Sheet'!H15/'Balance Sheet'!$B15*100 -> 258.83811 | I24: ='Balance Sheet'!I15/'Balance Sheet'!$B15*100 -> 260.55771 | J24: ='Balance Sheet'!J15/'Balance Sheet'!$B15*100 -> 306.0031 | ... M24: ='Balance Sheet'!M15/'Balance Sheet'!$B15*100 -> 450.78234
A25: Fixed Assets | B25: 100 | C25: ='Balance Sheet'!C16/'Balance Sheet'!$B16*100 -> 112.79007 | D25: ='Balance Sheet'!D16/'Balance Sheet'!$B16*100 -> 130.43713 | E25: ='Balance Sheet'!E16/'Balance Sheet'!$B16*100 -> 175.95791 | F25: ='Balance Sheet'!F16/'Balance Sheet'!$B16*100 -> 228.68322 | G25: ='Balance Sheet'!G16/'Balance Sheet'!$B16*100 -> 253.53481 | H25: ='Balance Sheet'!H16/'Balance Sheet'!$B16*100 -> 252.94118 | I25: ='Balance Sheet'!I16/'Balance Sheet'!$B16*100 -> 284.1878 | J25: ='Balance Sheet'!J16/'Balance Sheet'!$B16*100 -> 297.46357 | ... M25: ='Balance Sheet'!M16/'Balance Sheet'!$B16*100 -> 469.69779
A26: Intangible Assets | B26: 100 | C26: ='Balance Sheet'!C23/'Balance Sheet'!$B23*100 -> 81.624758 | D26: ='Balance Sheet'!D23/'Balance Sheet'!$B23*100 -> 80.851064 | E26: ='Balance Sheet'!E23/'Balance Sheet'!$B23*100 -> 190.90909 | F26: ='Balance Sheet'!F23/'Balance Sheet'!$B23*100 -> 296.80851 | G26: ='Balance Sheet'!G23/'Balance Sheet'!$B23*100 -> 335.00967 | H26: ='Balance Sheet'!H23/'Balance Sheet'!$B23*100 -> 346.32495 | I26: ='Balance Sheet'!I23/'Balance Sheet'!$B23*100 -> 379.88395 | J26: ='Balance Sheet'!J23/'Balance Sheet'!$B23*100 -> 487.33075 | ... M26: ='Balance Sheet'!M23/'Balance Sheet'!$B23*100 -> 678.62669
A27: CWIP | B27: 100 | C27: ='Balance Sheet'!C27/'Balance Sheet'!$B27*100 -> 201.90476 | D27: ='Balance Sheet'!D27/'Balance Sheet'!$B27*100 -> 347.14286 | E27: ='Balance Sheet'!E27/'Balance Sheet'!$B27*100 -> 376.90476 | F27: ='Balance Sheet'!F27/'Balance Sheet'!$B27*100 -> 397.14286 | G27: ='Balance Sheet'!G27/'Balance Sheet'!$B27*100 -> 472.85714 | H27: ='Balance Sheet'!H27/'Balance Sheet'!$B27*100 -> 729.04762 | I27: ='Balance Sheet'!I27/'Balance Sheet'!$B27*100 -> 892.14286 | J27: ='Balance Sheet'!J27/'Balance Sheet'!$B27*100 -> 1283.3333 | ... M27: ='Balance Sheet'!M27/'Balance Sheet'!$B27*100 -> 1241.4286
A28: Investments | B28: 100 | C28: ='Balance Sheet'!C28/'Balance Sheet'!$B28*100 -> 615 | D28: ='Balance Sheet'!D28/'Balance Sheet'!$B28*100 -> 1230 | E28: ='Balance Sheet'!E28/'Balance Sheet'!$B28*100 -> 1560 | F28: ='Balance Sheet'!F28/'Balance Sheet'!$B28*100 -> 1800 | G28: ='Balance Sheet'!G28/'Balance Sheet'!$B28*100 -> 2775 | H28: ='Balance Sheet'!H28/'Balance Sheet'!$B28*100 -> 2955 | I28: ='Balance Sheet'!I28/'Balance Sheet'!$B28*100 -> 4985 | J28: ='Balance Sheet'!J28/'Balance Sheet'!$B28*100 -> 2715 | ... M28: ='Balance Sheet'!M28/'Balance Sheet'!$B28*100 -> 5255
A29: Other Assets | B29: 100 | C29: ='Balance Sheet'!C29/'Balance Sheet'!$B29*100 -> 122.58985 | D29: ='Balance Sheet'!D29/'Balance Sheet'!$B29*100 -> 110.23388 | E29: ='Balance Sheet'!E29/'Balance Sheet'!$B29*100 -> 142.92071 | F29: ='Balance Sheet'!F29/'Balance Sheet'!$B29*100 -> 179.89732 | G29: ='Balance Sheet'!G29/'Balance Sheet'!$B29*100 -> 191.97946 | H29: ='Balance Sheet'!H29/'Balance Sheet'!$B29*100 -> 232.62978 | I29: ='Balance Sheet'!I29/'Balance Sheet'!$B29*100 -> 209.4923 | J29: ='Balance Sheet'!J29/'Balance Sheet'!$B29*100 -> 257.26184 | ... M29: ='Balance Sheet'!M29/'Balance Sheet'!$B29*100 -> 393.89618
A30: Inventories | B30: 100 | C30: ='Balance Sheet'!C30/'Balance Sheet'!$B30*100 -> 112.32346 | D30: ='Balance Sheet'!D30/'Balance Sheet'!$B30*100 -> 119.93908 | E30: ='Balance Sheet'!E30/'Balance Sheet'!$B30*100 -> 162.22653 | F30: ='Balance Sheet'!F30/'Balance Sheet'!$B30*100 -> 200.66464 | G30: ='Balance Sheet'!G30/'Balance Sheet'!$B30*100 -> 213.23733 | H30: ='Balance Sheet'!H30/'Balance Sheet'!$B30*100 -> 250.37386 | I30: ='Balance Sheet'!I30/'Balance Sheet'!$B30*100 -> 209.33259 | J30: ='Balance Sheet'!J30/'Balance Sheet'!$B30*100 -> 235.83495 | ... M30: ='Balance Sheet'!M30/'Balance Sheet'!$B30*100 -> 333.78565
A31: Trade Receivables | B31: 100 | C31: ='Balance Sheet'!C31/'Balance Sheet'!$B31*100 -> 130.17802 | D31: ='Balance Sheet'!D31/'Balance Sheet'!$B31*100 -> 78.129415 | E31: ='Balance Sheet'!E31/'Balance Sheet'!$B31*100 -> 87.030235 | F31: ='Balance Sheet'!F31/'Balance Sheet'!$B31*100 -> 96.467929 | G31: ='Balance Sheet'!G31/'Balance Sheet'!$B31*100 -> 121.9271 | H31: ='Balance Sheet'!H31/'Balance Sheet'!$B31*100 -> 98.982763 | I31: ='Balance Sheet'!I31/'Balance Sheet'!$B31*100 -> 113.36536 | J31: ='Balance Sheet'!J31/'Balance Sheet'!$B31*100 -> 126.19384 | ... M31: ='Balance Sheet'!M31/'Balance Sheet'!$B31*100 -> 200.45211
A32: Cash Equivalents | B32: 100 | C32: ='Balance Sheet'!C32/'Balance Sheet'!$B32*100 -> 170.57569 | D32: ='Balance Sheet'!D32/'Balance Sheet'!$B32*100 -> 109.38166 | E32: ='Balance Sheet'!E32/'Balance Sheet'!$B32*100 -> 269.08316 | F32: ='Balance Sheet'!F32/'Balance Sheet'!$B32*100 -> 417.27079 | G32: ='Balance Sheet'!G32/'Balance Sheet'!$B32*100 -> 605.97015 | H32: ='Balance Sheet'!H32/'Balance Sheet'!$B32*100 -> 1167.1642 | I32: ='Balance Sheet'!I32/'Balance Sheet'!$B32*100 -> 893.39019 | J32: ='Balance Sheet'!J32/'Balance Sheet'!$B32*100 -> 1297.2281 | ... M32: ='Balance Sheet'!M32/'Balance Sheet'!$B32*100 -> 2104.4776
A33: Total Assets | B33: 100 | C33: ='Balance Sheet'!C35/'Balance Sheet'!$B35*100 -> 123.12936 | D33: ='Balance Sheet'!D35/'Balance Sheet'!$B35*100 -> 125.48412 | E33: ='Balance Sheet'!E35/'Balance Sheet'!$B35*100 -> 162.21534 | F33: ='Balance Sheet'!F35/'Balance Sheet'!$B35*100 -> 203.49342 | G33: ='Balance Sheet'!G35/'Balance Sheet'!$B35*100 -> 222.81177 | H33: ='Balance Sheet'!H35/'Balance Sheet'!$B35*100 -> 258.83811 | I33: ='Balance Sheet'!I35/'Balance Sheet'!$B35*100 -> 260.55771 | J33: ='Balance Sheet'!J35/'Balance Sheet'!$B35*100 -> 306.0031 | ... M33: ='Balance Sheet'!M35/'Balance Sheet'!$B35*100 -> 450.78234

Sheet Ratio Analysis
A1: Ratio Analysis
A4: Liquidity
A6: Particulars | B6: 42064 | C6: 42430 | D6: 42795 | E6: 43160 | F6: 43525 | G6: 43891 | H6: 44256 | I6: 44621 | J6: 44986 | K6: 45352 | L6: 45717 | M6: 46082
A7: Current Ratio | B7: ='Balance Sheet'!B29/'Balance Sheet'!B10 -> 2.6536482 | C7: ='Balance Sheet'!C29/'Balance Sheet'!C10 -> 3.011491 | D7: ='Balance Sheet'!D29/'Balance Sheet'!D10 -> 2.789261 | E7: ='Balance Sheet'!E29/'Balance Sheet'!E10 -> 2.7887355 | F7: ='Balance Sheet'!F29/'Balance Sheet'!F10 -> 2.9124492 | G7: ='Balance Sheet'!G29/'Balance Sheet'!G10 -> 2.7526583 | H7: ='Balance Sheet'!H29/'Balance Sheet'!H10 -> 3.3170652 | I7: ='Balance Sheet'!I29/'Balance Sheet'!I10 -> 2.9563677 | ... M7: ='Balance Sheet'!M29/'Balance Sheet'!M10 -> 2.8225147
A8: Quick Ratio | B8: =('Balance Sheet'!B29-'Balance Sheet'!B30)/'Balance Sheet'!B10 -> 1.5603996 | C8: =('Balance Sheet'!C29-'Balance Sheet'!C30)/'Balance Sheet'!C10 -> 1.8747197 | D8: =('Balance Sheet'!D29-'Balance Sheet'!D30)/'Balance Sheet'!D10 -> 1.5389723 | E8: =('Balance Sheet'!E29-'Balance Sheet'!E30)/'Balance Sheet'!E10 -> 1.4846394 | F8: =('Balance Sheet'!F29-'Balance Sheet'!F30)/'Balance Sheet'!F10 -> 1.5740672 | G8: =('Balance Sheet'!G29-'Balance Sheet'!G30)/'Balance Sheet'!G10 -> 1.4930476 | H8: =('Balance Sheet'!H29-'Balance Sheet'!H30)/'Balance Sheet'!H10 -> 1.8462665 | I8: =('Balance Sheet'!I29-'Balance Sheet'!I30)/'Balance Sheet'!I10 -> 1.7393334 | ... M8: =('Balance Sheet'!M29-'Balance Sheet'!M30)/'Balance Sheet'!M10 -> 1.8371485
A10: Solvency
A12: Particulars | B12: 42064 | C12: 42430 | D12: 42795 | E12: 43160 | F12: 43525 | G12: 43891 | H12: 44256 | I12: 44621 | J12: 44986 | K12: 45352 | L12: 45717 | M12: 46082
A13: Debt-Equity Ratio | B13: ='Balance Sheet'!B4/('Balance Sheet'!B2+'Balance Sheet'!B3) -> 0.8632661 | C13: ='Balance Sheet'!C4/('Balance Sheet'!C2+'Balance Sheet'!C3) -> 0.69168496 | D13: ='Balance Sheet'!D4/('Balance Sheet'!D2+'Balance Sheet'!D3) -> 0.35894153 | E13: ='Balance Sheet'!E4/('Balance Sheet'!E2+'Balance Sheet'!E3) -> 0.40835545 | F13: ='Balance Sheet'!F4/('Balance Sheet'!F2+'Balance Sheet'!F3) -> 0.50154776 | G13: ='Balance Sheet'!G4/('Balance Sheet'!G2+'Balance Sheet'!G3) -> 0.34627043 | H13: ='Balance Sheet'!H4/('Balance Sheet'!H2+'Balance Sheet'!H3) -> 0.24345645 | I13: ='Balance Sheet'!I4/('Balance Sheet'!I2+'Balance Sheet'!I3) -> 0.11600749 | ... M13: ='Balance Sheet'!M4/('Balance Sheet'!M2+'Balance Sheet'!M3) -> 0.21305851
A14: Debt Ratio | B14: ='Balance Sheet'!B4/'Balance Sheet'!B35 -> 0.34477149 | C14: ='Balance Sheet'!C4/'Balance Sheet'!C35 -> 0.3171238 | D14: ='Balance Sheet'!D4/'Balance Sheet'!D35 -> 0.20765432 | E14: ='Balance Sheet'!E4/'Balance Sheet'!E35 -> 0.22777194 | F14: ='Balance Sheet'!F4/'Balance Sheet'!F35 -> 0.26519737 | G14: ='Balance Sheet'!G4/'Balance Sheet'!G35 -> 0.20253781 | H14: ='Balance Sheet'!H4/'Balance Sheet'!H35 -> 0.15977376 | I14: ='Balance Sheet'!I4/'Balance Sheet'!I35 -> 0.084755336 | ... M14: ='Balance Sheet'!M4/'Balance Sheet'!M35 -> 0.13872087
A16: Profitability
A18: Particulars | B18: 42064 | C18: 42430 | D18: 42795 | E18: 43160 | F18: 43525 | G18: 43891 | H18: 44256 | I18: 44621 | J18: 44986 | K18: 45352 | L18: 45717 | M18: 46082
A19: Operating Profit Margin | B19: =('Income Statement'!B11/'Income Statement'!B2) -> 0.21308766 | C19: =('Income Statement'!C11/'Income Statement'!C2) -> 0.23184723 | D19: =('Income Statement'!D11/'Income Statement'!D2) -> 0.23078471 | E19: =('Income Statement'!E11/'Income Statement'!E2) -> 0.22911984 | F19: =('Income Statement'!F11/'Income Statement'!F2) -> 0.20200368 | G19: =('Income Statement'!G11/'Income Statement'!G2) -> 0.20992251 | H19: =('Income Statement'!H11/'Income Statement'!H2) -> 0.21303734 | I19: =('Income Statement'!I11/'Income Statement'!I2) -> 0.18742272 | ... M19: =('Income Statement'!M11/'Income Statement'!M2) -> 0.20414228
